<mujoco model="manipulator">
    <compiler angle="radian" meshdir="../meshes/stl/" />
    <size njmax="500" nconmax="100" />
    <asset>
        <mesh name="BL_Finger_Holder_SIM" file="BL_Finger_Holder_SIM.stl" />
        <mesh name="Stage_simplified" file="Stage_simplified.stl" />
        <mesh name="SIM__BL-Finger_Proximal" file="SIM__BL-Finger_Proximal.stl" />
        <mesh name="SIM__BL-Finger_Base" file="SIM__BL-Finger_Base.stl" />
        <mesh name="SIM__BL-Finger_Intermediate" file="SIM__BL-Finger_Intermediate.stl" />
        <mesh name="SIM_BL_FINGER_TIP_LINK" file="SIM_BL_FINGER_TIP_LINK.stl" />
        <mesh name="finger_padding" file="finger_padding.stl" />
    </asset>
    <worldbody>
        <geom type="mesh" contype="0" conaffinity="0" group="1" rgba="0.8 0.8 0.8 0.8" mesh="BL_Finger_Holder_SIM" />
        <geom type="mesh" rgba="0.8 0.8 0.8 0.8" mesh="BL_Finger_Holder_SIM" />
        <geom pos="0 0 -0.2665" type="mesh" contype="0" conaffinity="0" group="1" rgba="0.8 0.8 0.8 0.8" mesh="Stage_simplified" />
        <geom pos="0 0 -0.2665" type="mesh" rgba="0.8 0.8 0.8 0.8" mesh="Stage_simplified" />
        <geom pos="0 0.20595 0" type="mesh" contype="0" conaffinity="0" group="1" rgba="0.8 0.8 0.8 0.8" mesh="SIM__BL-Finger_Base" />
        <geom pos="0 0.20595 0" type="mesh" rgba="0.8 0.8 0.8 0.8" mesh="SIM__BL-Finger_Base" />
        <body name="proximal_link" pos="0 0 0">
            <inertial pos="0 0 0" quat="0.707107 0.707107 0 0" mass="1" diaginertia="0.00391285 0.00386036 0.000317833" />
            <joint name="holder_to_proximal" pos="0 0 0" axis="0 1 0" limited="true" range="-1.5708 1.5708" />
            <geom type="mesh" contype="0" conaffinity="0" group="1" rgba="0.8 0.8 0.8 0.8" mesh="SIM__BL-Finger_Proximal" />
            <geom type="mesh" rgba="0.8 0.8 0.8 0.8" mesh="SIM__BL-Finger_Proximal" />
            <body name="intermediate_link" pos="0.014 0.02695 0">
                <inertial pos="0 0 0" quat="0.707107 0.707107 0 0" mass="0.95" diaginertia="0.00351471 0.0034985 0.000294181" />
                <joint name="proximal_to_intermediate" pos="0 0 0" axis="1 0 0" limited="true" range="-2.92343 2.92343" />
                <geom type="mesh" contype="0" conaffinity="0" group="1" rgba="0.8 0.8 0.8 0.8" mesh="SIM__BL-Finger_Intermediate" />
                <geom type="mesh" rgba="0.8 0.8 0.8 0.8" mesh="SIM__BL-Finger_Intermediate" />
                <body name="tip_link" pos="0 -0.16 0">
                    <inertial pos="-0.000595238 -0.00761905 0" quat="0.506001 0.493926 -0.506001 0.493926" mass="0.21" diaginertia="0.000816051 0.000812186 2.32316e-05" />
                    <joint name="intermediate_to_tip" pos="0 0 0" axis="1 0 0" limited="true" range="-3.00197 3.00197" />
                    <geom type="mesh" contype="0" conaffinity="0" group="1" rgba="0.8 0.8 0.8 0.8" mesh="SIM_BL_FINGER_TIP_LINK" />
                    <geom type="mesh" rgba="0.8 0.8 0.8 0.8" mesh="SIM_BL_FINGER_TIP_LINK" />
                    <geom pos="-0.0125 -0.16 0" type="mesh" contype="0" conaffinity="0" group="1" rgba="0.8 0.8 0.8 0.8" mesh="finger_padding" />
                    <geom pos="-0.0125 -0.16 0" type="mesh" rgba="0.8 0.8 0.8 0.8" mesh="finger_padding" />
                </body>
            </body>
        </body>
    </worldbody>
    
    <!--ACTUATORS-->
    <actuator>
        <motor name='holder_to_proximal' joint='holder_to_proximal' gear="10000"/>
        <motor name='proximal_to_intermediate' joint='proximal_to_intermediate' gear="0.1"/>
        <motor name='intermediate_to_tip' joint='intermediate_to_tip' gear="0.1"/>
    </actuator>
</mujoco>
