<mujoco model="manipulator">
    <compiler angle="radian" meshdir="../meshes/stl/" />
    <size njmax="500" nconmax="100" />
    <asset>
        <mesh name="BL_Finger_Holder_SIM" file="BL_Finger_Holder_SIM.stl" />
        <mesh name="Stage_simplified" file="Stage_simplified.stl" />
        <mesh name="SIM__BL-Finger_Proximal" file="SIM__BL-Finger_Proximal.stl" />
        <mesh name="SIM__BL-Finger_Base" file="SIM__BL-Finger_Base.stl" />
        <mesh name="SIM__BL-Finger_Intermediate" file="SIM__BL-Finger_Intermediate.stl" />
        <mesh name="SIM_BL_FINGER_TIP_LINK" file="SIM_BL_FINGER_TIP_LINK.stl" />
        <mesh name="finger_padding" file="finger_padding.stl" />
    </asset>
    <worldbody>
        <geom type="mesh" contype="0" conaffinity="0" group="1" rgba="0.8 0.8 0.8 0.8" mesh="BL_Finger_Holder_SIM" />
        <geom type="mesh" rgba="0.8 0.8 0.8 0.8" mesh="BL_Finger_Holder_SIM" />
        <geom pos="0 0 -0.2665" type="mesh" contype="0" conaffinity="0" group="1" rgba="0.8 0.8 0.8 0.8" mesh="Stage_simplified" />
        <geom pos="0 0 -0.2665" type="mesh" rgba="0.8 0.8 0.8 0.8" mesh="Stage_simplified" />
        <geom pos="0 0.20595 0" type="mesh" contype="0" conaffinity="0" group="1" rgba="0.8 0.8 0.8 0.8" mesh="SIM__BL-Finger_Base" />
        <geom pos="0 0.20595 0" type="mesh" rgba="0.8 0.8 0.8 0.8" mesh="SIM__BL-Finger_Base" />
        <body name="proximal_link" pos="0 0 0" quat="0.707105 0 -0.707108 0">
            <inertial pos="0 0 0" quat="0.707107 0.707107 0 0" mass="0.18" diaginertia="0.000704314 0.000694864 5.721e-05" />
            <joint name="holder_to_proximal" pos="0 0 0" axis="0 1 0" limited="true" range="0 3.14159" />
            <geom type="mesh" contype="0" conaffinity="0" group="1" rgba="0.8 0.8 0.8 0.8" mesh="SIM__BL-Finger_Proximal" />
            <geom type="mesh" rgba="0.8 0.8 0.8 0.8" mesh="SIM__BL-Finger_Proximal" />
            <body name="intermediate_link" pos="0.014 0.02695 0" quat="0.108867 0.994056 0 0">
                <inertial pos="0 0 0" quat="0.707107 0.707107 0 0" mass="0.18" diaginertia="0.000665945 0.000662874 5.57396e-05" />
                <joint name="proximal_to_intermediate" pos="0 0 0" axis="1 0 0" limited="true" range="-5.84685 0" />
                <geom type="mesh" contype="0" conaffinity="0" group="1" rgba="0.8 0.8 0.8 0.8" mesh="SIM__BL-Finger_Intermediate" />
                <geom type="mesh" rgba="0.8 0.8 0.8 0.8" mesh="SIM__BL-Finger_Intermediate" />
                <body name="tip_link" pos="0 -0.16 0" quat="0.0697546 -0.997564 0 0">
                    <inertial pos="-0.0025 -0.032 0" quat="0.512584 0.487091 -0.512584 0.487091" mass="0.025" diaginertia="0.000160167 0.000159667 2.50375e-06" />
                    <joint name="intermediate_to_tip" pos="0 0 0" axis="1 0 0" limited="true" range="0 6.00394" />
                    <geom type="mesh" contype="0" conaffinity="0" group="1" rgba="0.8 0.8 0.8 0.8" mesh="SIM_BL_FINGER_TIP_LINK" />
                    <geom type="mesh" rgba="0.8 0.8 0.8 0.8" mesh="SIM_BL_FINGER_TIP_LINK" />
                    <geom pos="-0.0125 -0.16 0" type="mesh" contype="0" conaffinity="0" group="1" rgba="0.8 0.8 0.8 0.8" mesh="finger_padding" />
                    <geom pos="-0.0125 -0.16 0" type="mesh" rgba="0.8 0.8 0.8 0.8" mesh="finger_padding" />
                </body>
            </body>
        </body>
    </worldbody>
</mujoco>
