<?xml version="1.0" encoding="utf-8"?>
<!-- =================================================================================== -->
<!-- |    This document was autogenerated by xacro from /is/ei/mwuthrich/blmc_ei/workspace/src/catkin/robots/robot_properties/robot_properties_manipulator/xacro/manipulator.urdf.xacro | -->
<!-- |    EDITING THIS FILE BY HAND IS NOT RECOMMENDED                                 | -->
<!-- =================================================================================== -->
<robot name="manipulator" xmlns:controller="http://playerstage.sourceforge.net/gazebo/xmlschema/#controller" xmlns:interface="http://playerstage.sourceforge.net/gazebo/xmlschema/#interface" xmlns:sensor="http://playerstage.sourceforge.net/gazebo/xmlschema/#sensor" xmlns:xacro="http://playerstage.sourceforge.net/gazebo/xmlschema/#interface">
  <mujoco>
    <compiler balanceinertia="true" discardvisual="false" meshdir="../meshes/stl/"/>
  </mujoco>
  <!-- World Link -->
  <link name="world"/>
  <!-- Dummy Link -->
  <link name="link0"/>
  <joint name="world_joint" type="fixed">
    <parent link="world"/>
    <child link="link0"/>
    <origin rpy="0 0 0" xyz="0 0 0"/>
    <axis xyz="0 0 1"/>
  </joint>
  <joint name="holder_joint" type="fixed">
    <parent link="link0"/>
    <child link="holder_link"/>
    <origin rpy="0 0 0" xyz="0 0 0"/>
  </joint>
  <link name="holder_link">
    <inertial>
      <origin rpy="0 0 0" xyz="0 0 0"/>
      <mass value="0.1"/>
      <inertia ixx="0.000166666666667" ixy="0" ixz="0" iyy="0.000166666666667" iyz="0" izz="0.000166666666667"/>
    </inertial>
    <visual>
      <origin rpy="0 0 0" xyz="0 0 0"/>
      <geometry>
        <mesh filename="package://robot_properties_manipulator/meshes/stl/BL_Finger_Holder_SIM.stl"/>
      </geometry>
      <material name="grey">
        <color rgba="0.8 0.8 0.8 0.8"/>
      </material>
    </visual>
    <collision>
      <origin rpy="0 0 0" xyz="0 0 0"/>
      <geometry>
        <mesh filename="package://robot_properties_manipulator/meshes/stl/BL_Finger_Holder_SIM.stl"/>
      </geometry>
      <material name="grey">
        <color rgba="0.8 0.8 0.8 0.8"/>
      </material>
    </collision>
  </link>
  <joint name="holder_to_stage" type="fixed">
    <parent link="holder_link"/>
    <child link="stage_link"/>
    <origin xyz="0 0 -0.2665"/>
  </joint>
  <link name="stage_link">
    <inertial>
      <origin rpy="0 0 0" xyz="0 0 0"/>
      <mass value="5"/>
      <inertia ixx="0.108333333333" ixy="0" ixz="0" iyy="0.108333333333" iyz="0" izz="0.208333333333"/>
    </inertial>
    <visual>
      <origin rpy="0 0 0" xyz="0 0 0"/>
      <geometry>
        <mesh filename="package://robot_properties_manipulator/meshes/stl/Stage_simplified.stl"/>
      </geometry>
      <material name="grey">
        <color rgba="0.8 0.8 0.8 0.8"/>
      </material>
    </visual>
    <collision>
      <origin rpy="0 0 0" xyz="0 0 0"/>
      <geometry>
        <mesh filename="package://robot_properties_manipulator/meshes/stl/Stage_simplified.stl"/>
      </geometry>
      <material name="grey">
        <color rgba="0.8 0.8 0.8 0.8"/>
      </material>
    </collision>
  </link>
  <joint name="holder_to_proximal" type="revolute">
    <parent link="holder_link"/>
    <child link="proximal_link"/>
    <limit effort="1000" lower="0" upper="3.14159265359" velocity="1000"/>
    <axis rpy="0 0 0" xyz="0 1 0"/>
    <origin rpy="0 -1.5708 0" xyz="0 0 0"/>
  </joint>
  <link name="proximal_link">
    <inertial>
      <origin rpy="0 0 0" xyz="0 0 0"/>
      <mass value="0.18"/>
      <inertia ixx="0.00070431361566" ixy="0" ixz="0" iyy="5.721001566e-05" iyz="0" izz="0.0006948639"/>
    </inertial>
    <visual>
      <origin rpy="0 0 0" xyz="0 0 0"/>
      <geometry>
        <mesh filename="package://robot_properties_manipulator/meshes/stl/SIM__BL-Finger_Proximal.stl"/>
      </geometry>
      <material name="grey">
        <color rgba="0.8 0.8 0.8 0.8"/>
      </material>
    </visual>
    <collision>
      <origin rpy="0 0 0" xyz="0 0 0"/>
      <geometry>
        <mesh filename="package://robot_properties_manipulator/meshes/stl/SIM__BL-Finger_Proximal.stl"/>
      </geometry>
      <material name="grey">
        <color rgba="0.8 0.8 0.8 0.8"/>
      </material>
    </collision>
  </link>
  <joint name="holder_to_base" type="fixed">
    <parent link="holder_link"/>
    <child link="base_link"/>
    <origin xyz="0 0.20595 0"/>
  </joint>
  <link name="base_link">
    <inertial>
      <origin rpy="0 0 0" xyz="0 0 0"/>
      <mass value="0.1"/>
      <inertia ixx="0.000166666666667" ixy="0" ixz="0" iyy="0.000166666666667" iyz="0" izz="0.000166666666667"/>
    </inertial>
    <visual>
      <origin rpy="0 0 0" xyz="0 0 0"/>
      <geometry>
        <mesh filename="package://robot_properties_manipulator/meshes/stl/SIM__BL-Finger_Base.stl"/>
      </geometry>
      <material name="grey">
        <color rgba="0.8 0.8 0.8 0.8"/>
      </material>
    </visual>
    <collision>
      <origin rpy="0 0 0" xyz="0 0 0"/>
      <geometry>
        <mesh filename="package://robot_properties_manipulator/meshes/stl/SIM__BL-Finger_Base.stl"/>
      </geometry>
      <material name="grey">
        <color rgba="0.8 0.8 0.8 0.8"/>
      </material>
    </collision>
  </link>
  <joint name="proximal_to_intermediate" type="revolute">
    <parent link="proximal_link"/>
    <child link="intermediate_link"/>
    <limit effort="1000" lower="-5.846853" upper="0" velocity="1000"/>
    <axis rpy="0 0 0" xyz="1 0 0"/>
    <origin rpy="2.9234265 0 0" xyz="0.014 0.02695 0"/>
  </joint>
  <link name="intermediate_link">
    <inertial>
      <origin rpy="0 0 0" xyz="0 0 0"/>
      <mass value="0.18"/>
      <inertia ixx="0.00066594546264" ixy="0" ixz="0" iyy="5.573961264e-05" iyz="0" izz="0.00066287415"/>
    </inertial>
    <visual>
      <origin rpy="0 0 0" xyz="0 0 0"/>
      <geometry>
        <mesh filename="package://robot_properties_manipulator/meshes/stl/SIM__BL-Finger_Intermediate.stl"/>
      </geometry>
      <material name="grey">
        <color rgba="0.8 0.8 0.8 0.8"/>
      </material>
    </visual>
    <collision>
      <origin rpy="0 0 0" xyz="0 0 0"/>
      <geometry>
        <mesh filename="package://robot_properties_manipulator/meshes/stl/SIM__BL-Finger_Intermediate.stl"/>
      </geometry>
      <material name="grey">
        <color rgba="0.8 0.8 0.8 0.8"/>
      </material>
    </collision>
  </link>
  <joint name="intermediate_to_tip" type="revolute">
    <parent link="intermediate_link"/>
    <child link="tip_link"/>
    <limit effort="1000" lower="0" upper="6.00394" velocity="1000"/>
    <axis rpy="0 0 0" xyz="1 0 0"/>
    <origin rpy="-3.00197 0 0" xyz="0 -0.16 0"/>
  </joint>
  <link name="tip_link">
    <inertial>
      <origin rpy="0 0 0" xyz="0 0 0"/>
      <mass value="0.02"/>
      <inertia ixx="5.6775e-05" ixy="0" ixz="0" iyy="2.20369748167e-06" iyz="0" izz="5.70586974817e-05"/>
    </inertial>
    <visual>
      <origin rpy="0 0 0" xyz="0 0 0"/>
      <geometry>
        <mesh filename="package://robot_properties_manipulator/meshes/stl/SIM_BL_FINGER_TIP_LINK.stl"/>
      </geometry>
      <material name="grey">
        <color rgba="0.8 0.8 0.8 0.8"/>
      </material>
    </visual>
    <collision>
      <origin rpy="0 0 0" xyz="0 0 0"/>
      <geometry>
        <mesh filename="package://robot_properties_manipulator/meshes/stl/SIM_BL_FINGER_TIP_LINK.stl"/>
      </geometry>
      <material name="grey">
        <color rgba="0.8 0.8 0.8 0.8"/>
      </material>
    </collision>
  </link>
  <joint name="tip_to_padding" type="fixed">
    <parent link="tip_link"/>
    <child link="padding_link"/>
    <origin xyz="-0.0125 -0.16 0"/>
  </joint>
  <link name="padding_link">
    <inertial>
      <origin rpy="0 0 0" xyz="0 0 0"/>
      <mass value="0.005"/>
      <inertia ixx="8.33333333333e-08" ixy="0" ixz="0" iyy="8.33333333333e-08" iyz="0" izz="8.33333333333e-08"/>
    </inertial>
    <visual>
      <origin rpy="0 0 0" xyz="0 0 0"/>
      <geometry>
        <mesh filename="package://robot_properties_manipulator/meshes/stl/finger_padding.stl"/>
      </geometry>
      <material name="grey">
        <color rgba="0.8 0.8 0.8 0.8"/>
      </material>
    </visual>
    <collision>
      <origin rpy="0 0 0" xyz="0 0 0"/>
      <geometry>
        <mesh filename="package://robot_properties_manipulator/meshes/stl/finger_padding.stl"/>
      </geometry>
      <material name="grey">
        <color rgba="0.8 0.8 0.8 0.8"/>
      </material>
    </collision>
  </link>
  <!--    <actuator>
        <motor name="holder_to_proximal"        gear="100" joint="holder_to_proximal" />
        <motor name="proximal_to_intermediate"  gear="100" joint="proximal_to_intermediate" />
        <motor name="intermediate_to_tip"       gear="100" joint="intermediate_to_tip" />
    </actuator>-->
  <!--    <transmission name="holder_to_proximal">
        <joint name="holder_to_proximal" />
        <actuator name="holder_to_proximal">
            <mechanicalReduction>50</mechanicalReduction>
        </actuator>
    </transmission> -->
</robot>
